Workbook

Sheet START HERE
A1: EXCEL CAPSTONE PROJECT — Q1 2026 BUSINESS PERFORMANCE REPORT
A2: Prepared for: Anotida Kanzara | B2: Level: Intermediate
A4: YOUR MISSION
A5: The CEO needs a board-ready report by Friday. You have 4 messy data sheets.
A6: Complete every task below in order.
A8: SHEET | B8: TASK | C8: SKILLS APPLIED
A9: RAW SALES DATA | B9: 1. Remove duplicate transactions 2. Standardise Branch, Region & Status columns 3. Fix mixed date formats 4. Remove extra spaces from Rep names 5. Fix 3 blank customer names 6. Fix 'N/A' and 'TBC' in Revenue column 7. Correct 4 wrong revenue calculations 8. Flag negative quantities (returns) 9. Add Revenue Check column (Qty × Price) 10. Add IFERROR() around any broken formulas | C9: Data Cleaning: TRIM, PROPER, Find & Replace, IFERROR, Remove Duplicates
A10: PRODUCT CATALOGUE | B10: 11. Use XLOOKUP to pull Product Name, Category and Cost Price into Sales sheet 12. Add a Profit column (Revenue - Cost) 13. Add a Profit Margin % column | C10: XLOOKUP (absolute refs), Calculated Columns
A11: STAFF TABLE | B11: 14. Use XLOOKUP to pull Rep Name, Branch and Commission Rate into Sales sheet 15. Add Commission Earned column (Revenue × Rate) 16. Add a Performance Flag: 'Star' if Revenue >R20,000, else 'Standard' | C11: XLOOKUP, IF statements
A12: CLEANED DATA | B12: 17. Paste all cleaned and enriched data here 18. Format as Excel Table (Ctrl+T) 19. Apply currency formatting to all money columns 20. Freeze top row | C12: Table formatting, Number formatting
A13: REPORT SHEET | B13: 21. Build PivotTable 1: Revenue by Branch 22. Build PivotTable 2: Revenue by Product Category 23. Build PivotTable 3: Top Sales Reps 24. Build PivotTable 4: Revenue by Month 25. Create Bar Chart from PivotTable 1 26. Create Pie Chart from PivotTable 2 27. Create sorted Bar Chart from PivotTable 3 28. Create Line Chart from PivotTable 4 29. Fill in the Executive Summary section 30. Add Slicers to filter by Branch and Month | C13: PivotTables, Charts, Slicers
A15: STRETCH CHALLENGES (BONUS)
A16: Add a COUNTIF to count how many orders each branch placed
A17: Use AVERAGEIF to find average order value per region
A18: Add conditional formatting: top 10% revenue rows in green, bottom 10% in red
A19: Add a dropdown validation list for the Status column

Sheet PRODUCT CATALOGUE
A1: ProductID | B1: Product Name | C1: Category | D1: Unit Price (R) | E1: Cost Price (R) | F1: Supplier
A2: PR01 | B2: Gaming Laptop | C2: Electronics | D2: 15000 | E2: 9800 | F2: TechSource SA
A3: PR02 | B3: Office Chair | C3: Furniture | D3: 3200 | E3: 1750 | F3: FurniPro
A4: PR03 | B4: Wireless Headset | C4: Electronics | D4: 1800 | E4: 950 | F4: TechSource SA
A5: PR04 | B5: Standing Desk | C5: Furniture | D5: 5500 | E5: 3100 | F5: FurniPro
A6: PR05 | B6: Webcam HD | C6: Electronics | D6: 1200 | E6: 620 | F6: TechSource SA
A7: PR06 | B7: Notebook Bundle | C7: Stationery | D7: 350 | E7: 140 | F7: PaperWorks
A8: PR07 | B8: Mechanical Keyboard | C8: Electronics | D8: 2100 | E8: 1100 | F8: TechSource SA
A9: PR08 | B9: Whiteboard | C9: Stationery | D9: 890 | E9: 420 | F9: PaperWorks
A10: PR09 | B10: Monitor 27inch | C10: Electronics | D10: 4800 | E10: 2900 | F10: TechSource SA
A11: PR10 | B11: Ergonomic Mouse | C11: Electronics | D11: 650 | E11: 310 | F11: TechSource SA
A12: PR11 | B12: Filing Cabinet | C12: Furniture | D12: 2800 | E12: 1600 | F12: FurniPro
A13: PR12 | B13: Printer Paper Ream | C13: Stationery | D13: 120 | E13: 55 | F13: PaperWorks

Sheet STAFF TABLE
A1: EmpID | B1: Rep Name | C1: Branch | D1: Region | E1: Commission Rate | F1: Target (R)
A2: EM01 | B2: Thabo Nkosi | C2: Sandton Branch | D2: Gauteng | E2: 0.08 | F2: 80000
A3: EM02 | B3: Priya Pillay | C3: Durban Branch | D3: KZN | E3: 0.1 | F3: 75000
A4: EM03 | B4: Zanele Dlamini | C4: Cape Town Branch | D4: Western Cape | E4: 0.09 | F4: 85000
A5: EM04 | B5: Riaan Botha | C5: Sandton Branch | D5: Gauteng | E5: 0.08 | F5: 80000
A6: EM05 | B6: Amahle Zulu | C6: Durban Branch | D6: KZN | E6: 0.1 | F6: 75000
A7: EM06 | B7: Lebo Mahlangu | C7: Polokwane Branch | D7: Limpopo | E7: 0.07 | F7: 60000
A8: EM07 | B8: Fatima Patel | C8: Cape Town Branch | D8: Western Cape | E8: 0.09 | F8: 85000
A9: EM08 | B9: Kefilwe Sithole | C9: Sandton Branch | D9: Gauteng | E9: 0.08 | F9: 80000
A10: EM09 | B10: David Moyo | C10: Polokwane Branch | D10: Limpopo | E10: 0.07 | F10: 60000
A11: EM10 | B11: Sipho Dlamini | C11: Durban Branch | D11: KZN | E11: 0.1 | F11: 75000

Sheet RAW SALES DATA
A1: TxnID | B1: Date | C1: EmpID | D1: ProductID | E1: CustomerName | F1: Quantity | G1: Unit Price (R) | H1: Total Revenue (R) | I1: Status | J1: Rep Name ← XLOOKUP | K1: Branch | L1: Region | M1: Commission Rate | N1: Product Name ← XLOOKUP | O1: Category | P1: Cost Price (R) | Q1: Revenue Check ← CALCULATE | R1: Profit (R) | S1: Profit Margin % | T1: Commission Earned (R) | U1: Performance Flag
A2: TXN001 | B2: 2026-01-05 | C2: EM01 | D2: PR09 | E2: Fatima Patel | F2: 2 | G2: 4800 | H2: 9600 | I2: COMPLETED | J2: =_xlfn.XLOOKUP(C2,'STAFF TABLE'!A2:A11,'STAFF TABLE'!B2:B11) -> Thabo Nkosi | K2: =_xlfn.XLOOKUP(C2,'STAFF TABLE'!$A$2:$A$11,'STAFF TABLE'!$C$2:$C$11) -> Sandton Branch | L2: =_xlfn.XLOOKUP(C2,'STAFF TABLE'!$A$2:$A$11,'STAFF TABLE'!$D$2:$D$11) -> Gauteng | M2: =_xlfn.XLOOKUP(C2,'STAFF TABLE'!$A$2:$A$11,'STAFF TABLE'!$E$2:$E$11) -> 0.08 | N2: =_xlfn.XLOOKUP(D2,'PRODUCT CATALOGUE'!$A$2:$A$13,'PRODUCT CATALOGUE'!$B$2:$B$13) -> Monitor 27inch | O2: =_xlfn.XLOOKUP(D2,'PRODUCT CATALOGUE'!$A$2:$A$13,'PRODUCT CATALOGUE'!$C$2:$C$13) -> Electronics | P2: =_xlfn.XLOOKUP(D2,'PRODUCT CATALOGUE'!$A$2:$A$13,'PRODUCT CATALOGUE'!$E$2:$E$13) -> 2900 | Q2: 9600 | R2: =Q2-P2 -> 6700 | S2: =R2/Q2 -> 0.69791667 | T2: =M2*Q2 -> 768 | U2: =IF(S2>100%,"false","good") -> good
A3: TXN002 | B3: 05/01/2026 | C3: EM03 | D3: PR01 | F3: 1 | G3: 15000 | H3: 15000 | I3: COMPLETED | J3: =_xlfn.XLOOKUP(C3,'STAFF TABLE'!A3:A12,'STAFF TABLE'!B3:B12) -> Zanele Dlamini | K3: =_xlfn.XLOOKUP(C3,'STAFF TABLE'!$A$2:$A$11,'STAFF TABLE'!$C$2:$C$11) -> Cape Town Branch | L3: =_xlfn.XLOOKUP(C3,'STAFF TABLE'!$A$2:$A$11,'STAFF TABLE'!$D$2:$D$11) -> Western Cape | M3: =_xlfn.XLOOKUP(C3,'STAFF TABLE'!$A$2:$A$11,'STAFF TABLE'!$E$2:$E$11) -> 0.09 | N3: =_xlfn.XLOOKUP(D3,'PRODUCT CATALOGUE'!$A$2:$A$13,'PRODUCT CATALOGUE'!$B$2:$B$13) -> Gaming Laptop | O3: =_xlfn.XLOOKUP(D3,'PRODUCT CATALOGUE'!$A$2:$A$13,'PRODUCT CATALOGUE'!$C$2:$C$13) -> Electronics | P3: =_xlfn.XLOOKUP(D3,'PRODUCT CATALOGUE'!$A$2:$A$13,'PRODUCT CATALOGUE'!$E$2:$E$13) -> 9800 | Q3: 15000 | R3: =Q3-P3 -> 5200 | S3: =R3/Q3 -> 0.34666667 | T3: =M3*Q3 -> 1350 | U3: =IF(S3>100%,"false","good") -> good
A4: TXN003 | B4: 2026-01-06 | C4: EM05 | D4: PR07 | E4: Nomsa Khumalo | F4: 3 | G4: 2100 | H4: 6300 | I4: COMPLETED | J4: =_xlfn.XLOOKUP(C4,'STAFF TABLE'!A4:A13,'STAFF TABLE'!B4:B13) -> Amahle Zulu | K4: =_xlfn.XLOOKUP(C4,'STAFF TABLE'!$A$2:$A$11,'STAFF TABLE'!$C$2:$C$11) -> Durban Branch | L4: =_xlfn.XLOOKUP(C4,'STAFF TABLE'!$A$2:$A$11,'STAFF TABLE'!$D$2:$D$11) -> KZN | M4: =_xlfn.XLOOKUP(C4,'STAFF TABLE'!$A$2:$A$11,'STAFF TABLE'!$E$2:$E$11) -> 0.1 | N4: =_xlfn.XLOOKUP(D4,'PRODUCT CATALOGUE'!$A$2:$A$13,'PRODUCT CATALOGUE'!$B$2:$B$13) -> Mechanical Keyboard | O4: =_xlfn.XLOOKUP(D4,'PRODUCT CATALOGUE'!$A$2:$A$13,'PRODUCT CATALOGUE'!$C$2:$C$13) -> Electronics | P4: =_xlfn.XLOOKUP(D4,'PRODUCT CATALOGUE'!$A$2:$A$13,'PRODUCT CATALOGUE'!$E$2:$E$13) -> 1100 | Q4: 6300 | R4: =Q4-P4 -> 5200 | S4: =R4/Q4 -> 0.82539683 | T4: =M4*Q4 -> 630 | U4: =IF(S4>100%,"false","good") -> good
A5: TXN004 | B5: 2026-01-06 | C5: EM02 | D5: PR04 | E5: Pieter van Wyk | F5: 1 | G5: 5500 | H5: 5500 | I5: COMPLETED | J5: =_xlfn.XLOOKUP(C5,'STAFF TABLE'!A2:A11,'STAFF TABLE'!B2:B11) -> Priya Pillay | K5: =_xlfn.XLOOKUP(C5,'STAFF TABLE'!$A$2:$A$11,'STAFF TABLE'!$C$2:$C$11) -> Durban Branch | L5: =_xlfn.XLOOKUP(C5,'STAFF TABLE'!$A$2:$A$11,'STAFF TABLE'!$D$2:$D$11) -> KZN | M5: =_xlfn.XLOOKUP(C5,'STAFF TABLE'!$A$2:$A$11,'STAFF TABLE'!$E$2:$E$11) -> 0.1 | N5: =_xlfn.XLOOKUP(D5,'PRODUCT CATALOGUE'!$A$2:$A$13,'PRODUCT CATALOGUE'!$B$2:$B$13) -> Standing Desk | O5: =_xlfn.XLOOKUP(D5,'PRODUCT CATALOGUE'!$A$2:$A$13,'PRODUCT CATALOGUE'!$C$2:$C$13) -> Furniture | P5: =_xlfn.XLOOKUP(D5,'PRODUCT CATALOGUE'!$A$2:$A$13,'PRODUCT CATALOGUE'!$E$2:$E$13) -> 3100 | Q5: 5500 | R5: =Q5-P5 -> 2400 | S5: =R5/Q5 -> 0.43636364 | T5: =M5*Q5 -> 550 | U5: =IF(S5>100%,"false","good") -> good
A6: TXN005 | B6: 2026-01-07 | C6: EM08 | D6: PR06 | E6: Kefilwe Sithole | F6: 2 | G6: 350 | H6: 700 | I6: COMPLETED | J6: =_xlfn.XLOOKUP(C6,'STAFF TABLE'!A6:A15,'STAFF TABLE'!B6:B15) -> Kefilwe Sithole | K6: =_xlfn.XLOOKUP(C6,'STAFF TABLE'!$A$2:$A$11,'STAFF TABLE'!$C$2:$C$11) -> Sandton Branch | L6: =_xlfn.XLOOKUP(C6,'STAFF TABLE'!$A$2:$A$11,'STAFF TABLE'!$D$2:$D$11) -> Gauteng | M6: =_xlfn.XLOOKUP(C6,'STAFF TABLE'!$A$2:$A$11,'STAFF TABLE'!$E$2:$E$11) -> 0.08 | N6: =_xlfn.XLOOKUP(D6,'PRODUCT CATALOGUE'!$A$2:$A$13,'PRODUCT CATALOGUE'!$B$2:$B$13) -> Notebook Bundle | O6: =_xlfn.XLOOKUP(D6,'PRODUCT CATALOGUE'!$A$2:$A$13,'PRODUCT CATALOGUE'!$C$2:$C$13) -> Stationery | P6: =_xlfn.XLOOKUP(D6,'PRODUCT CATALOGUE'!$A$2:$A$13,'PRODUCT CATALOGUE'!$E$2:$E$13) -> 140 | Q6: 700 | R6: =Q6-P6 -> 560 | S6: =R6/Q6 -> 0.8 | T6: =M6*Q6 -> 56 | U6: =IF(S6>100%,"false","good") -> good
A7: TXN006 | B7: 2026-01-07 | C7: EM06 | D7: PR02 | E7: Sipho Dlamini | F7: 1 | G7: 3200 | H7: 3200 | I7: PENDING | J7: =_xlfn.XLOOKUP(C7,'STAFF TABLE'!A7:A16,'STAFF TABLE'!B7:B16) -> Lebo Mahlangu | K7: =_xlfn.XLOOKUP(C7,'STAFF TABLE'!$A$2:$A$11,'STAFF TABLE'!$C$2:$C$11) -> Polokwane Branch | L7: =_xlfn.XLOOKUP(C7,'STAFF TABLE'!$A$2:$A$11,'STAFF TABLE'!$D$2:$D$11) -> Limpopo | M7: =_xlfn.XLOOKUP(C7,'STAFF TABLE'!$A$2:$A$11,'STAFF TABLE'!$E$2:$E$11) -> 0.07 | N7: =_xlfn.XLOOKUP(D7,'PRODUCT CATALOGUE'!$A$2:$A$13,'PRODUCT CATALOGUE'!$B$2:$B$13) -> Office Chair | O7: =_xlfn.XLOOKUP(D7,'PRODUCT CATALOGUE'!$A$2:$A$13,'PRODUCT CATALOGUE'!$C$2:$C$13) -> Furniture | P7: =_xlfn.XLOOKUP(D7,'PRODUCT CATALOGUE'!$A$2:$A$13,'PRODUCT CATALOGUE'!$E$2:$E$13) -> 1750 | Q7: 3200 | R7: =Q7-P7 -> 1450 | S7: =R7/Q7 -> 0.453125 | T7: =M7*Q7 -> 224 | U7: =IF(S7>100%,"false","good") -> good
A8: TXN007 | B8: 07/01/2026 | C8: EM01 | D8: PR10 | E8: David Moyo | F8: 5 | G8: 650 | H8: 3250 | I8: COMPLETED | J8: =_xlfn.XLOOKUP(C8,'STAFF TABLE'!A2:A11,'STAFF TABLE'!B2:B11) -> Thabo Nkosi | K8: =_xlfn.XLOOKUP(C8,'STAFF TABLE'!$A$2:$A$11,'STAFF TABLE'!$C$2:$C$11) -> Sandton Branch | L8: =_xlfn.XLOOKUP(C8,'STAFF TABLE'!$A$2:$A$11,'STAFF TABLE'!$D$2:$D$11) -> Gauteng | M8: =_xlfn.XLOOKUP(C8,'STAFF TABLE'!$A$2:$A$11,'STAFF TABLE'!$E$2:$E$11) -> 0.08 | N8: =_xlfn.XLOOKUP(D8,'PRODUCT CATALOGUE'!$A$2:$A$13,'PRODUCT CATALOGUE'!$B$2:$B$13) -> Ergonomic Mouse | O8: =_xlfn.XLOOKUP(D8,'PRODUCT CATALOGUE'!$A$2:$A$13,'PRODUCT CATALOGUE'!$C$2:$C$13) -> Electronics | P8: =_xlfn.XLOOKUP(D8,'PRODUCT CATALOGUE'!$A$2:$A$13,'PRODUCT CATALOGUE'!$E$2:$E$13) -> 310 | Q8: 3250 | R8: =Q8-P8 -> 2940 | S8: =R8/Q8 -> 0.90461538 | T8: =M8*Q8 -> 260 | U8: =IF(S8>100%,"false","good") -> good
A9: TXN008 | B9: 2026-01-08 | C9: EM04 | D9: PR03 | E9: Priya Pillay | F9: 4 | G9: 1800 | H9: 7200 | I9: COMPLETED | J9: =_xlfn.XLOOKUP(C9,'STAFF TABLE'!A3:A12,'STAFF TABLE'!B3:B12) -> Riaan Botha | K9: =_xlfn.XLOOKUP(C9,'STAFF TABLE'!$A$2:$A$11,'STAFF TABLE'!$C$2:$C$11) -> Sandton Branch | L9: =_xlfn.XLOOKUP(C9,'STAFF TABLE'!$A$2:$A$11,'STAFF TABLE'!$D$2:$D$11) -> Gauteng | M9: =_xlfn.XLOOKUP(C9,'STAFF TABLE'!$A$2:$A$11,'STAFF TABLE'!$E$2:$E$11) -> 0.08 | N9: =_xlfn.XLOOKUP(D9,'PRODUCT CATALOGUE'!$A$2:$A$13,'PRODUCT CATALOGUE'!$B$2:$B$13) -> Wireless Headset | O9: =_xlfn.XLOOKUP(D9,'PRODUCT CATALOGUE'!$A$2:$A$13,'PRODUCT CATALOGUE'!$C$2:$C$13) -> Electronics | P9: =_xlfn.XLOOKUP(D9,'PRODUCT CATALOGUE'!$A$2:$A$13,'PRODUCT CATALOGUE'!$E$2:$E$13) -> 950 | Q9: 7200 | R9: =Q9-P9 -> 6250 | S9: =R9/Q9 -> 0.86805556 | T9: =M9*Q9 -> 576 | U9: =IF(S9>100%,"false","good") -> good
A10: TXN009 | B10: 2026-01-08 | C10: EM07 | D10: PR01 | E10: Zanele Mokoena | F10: 2 | G10: 15000 | H10: 25000 | I10: COMPLETED | J10: =_xlfn.XLOOKUP(C10,'STAFF TABLE'!A4:A13,'STAFF TABLE'!B4:B13) -> Fatima Patel | K10: =_xlfn.XLOOKUP(C10,'STAFF TABLE'!$A$2:$A$11,'STAFF TABLE'!$C$2:$C$11) -> Cape Town Branch | L10: =_xlfn.XLOOKUP(C10,'STAFF TABLE'!$A$2:$A$11,'STAFF TABLE'!$D$2:$D$11) -> Western Cape | M10: =_xlfn.XLOOKUP(C10,'STAFF TABLE'!$A$2:$A$11,'STAFF TABLE'!$E$2:$E$11) -> 0.09 | N10: =_xlfn.XLOOKUP(D10,'PRODUCT CATALOGUE'!$A$2:$A$13,'PRODUCT CATALOGUE'!$B$2:$B$13) -> Gaming Laptop | O10: =_xlfn.XLOOKUP(D10,'PRODUCT CATALOGUE'!$A$2:$A$13,'PRODUCT CATALOGUE'!$C$2:$C$13) -> Electronics | P10: =_xlfn.XLOOKUP(D10,'PRODUCT CATALOGUE'!$A$2:$A$13,'PRODUCT CATALOGUE'!$E$2:$E$13) -> 9800 | Q10: 30000 | R10: =Q10-P10 -> 20200 | S10: =R10/Q10 -> 0.67333333 | T10: =M10*Q10 -> 2700 | U10: =IF(S10>100%,"false","good") -> good
A11: TXN010 | B11: 2026-01-09 | C11: EM10 | D11: PR08 | F11: 3 | G11: 890 | H11: 2670 | I11: CANCELLED | J11: =_xlfn.XLOOKUP(C11,'STAFF TABLE'!A5:A14,'STAFF TABLE'!B5:B14) -> Sipho Dlamini | K11: =_xlfn.XLOOKUP(C11,'STAFF TABLE'!$A$2:$A$11,'STAFF TABLE'!$C$2:$C$11) -> Durban Branch | L11: =_xlfn.XLOOKUP(C11,'STAFF TABLE'!$A$2:$A$11,'STAFF TABLE'!$D$2:$D$11) -> KZN | M11: =_xlfn.XLOOKUP(C11,'STAFF TABLE'!$A$2:$A$11,'STAFF TABLE'!$E$2:$E$11) -> 0.1 | N11: =_xlfn.XLOOKUP(D11,'PRODUCT CATALOGUE'!$A$2:$A$13,'PRODUCT CATALOGUE'!$B$2:$B$13) -> Whiteboard | O11: =_xlfn.XLOOKUP(D11,'PRODUCT CATALOGUE'!$A$2:$A$13,'PRODUCT CATALOGUE'!$C$2:$C$13) -> Stationery | P11: =_xlfn.XLOOKUP(D11,'PRODUCT CATALOGUE'!$A$2:$A$13,'PRODUCT CATALOGUE'!$E$2:$E$13) -> 420 | Q11: 2670 | R11: =Q11-P11 -> 2250 | S11: =R11/Q11 -> 0.84269663 | T11: =M11*Q11 -> 267 | U11: =IF(S11>100%,"false","good") -> good
A12: TXN011 | B12: 2026-01-09 | C12: EM03 | D12: PR09 | E12: Riaan Botha | F12: 1 | G12: 4800 | H12: 4800 | I12: COMPLETED | J12: =_xlfn.XLOOKUP(C12,'STAFF TABLE'!A2:A11,'STAFF TABLE'!B2:B11) -> Zanele Dlamini | K12: =_xlfn.XLOOKUP(C12,'STAFF TABLE'!$A$2:$A$11,'STAFF TABLE'!$C$2:$C$11) -> Cape Town Branch | L12: =_xlfn.XLOOKUP(C12,'STAFF TABLE'!$A$2:$A$11,'STAFF TABLE'!$D$2:$D$11) -> Western Cape | M12: =_xlfn.XLOOKUP(C12,'STAFF TABLE'!$A$2:$A$11,'STAFF TABLE'!$E$2:$E$11) -> 0.09 | N12: =_xlfn.XLOOKUP(D12,'PRODUCT CATALOGUE'!$A$2:$A$13,'PRODUCT CATALOGUE'!$B$2:$B$13) -> Monitor 27inch | O12: =_xlfn.XLOOKUP(D12,'PRODUCT CATALOGUE'!$A$2:$A$13,'PRODUCT CATALOGUE'!$C$2:$C$13) -> Electronics | P12: =_xlfn.XLOOKUP(D12,'PRODUCT CATALOGUE'!$A$2:$A$13,'PRODUCT CATALOGUE'!$E$2:$E$13) -> 2900 | Q12: 4800 | R12: =Q12-P12 -> 1900 | S12: =R12/Q12 -> 0.39583333 | T12: =M12*Q12 -> 432 | U12: =IF(S12>100%,"false","good") -> good
A13: TXN012 | B13: 09/01/2026 | C13: EM05 | D13: PR12 | E13: Amahle Zulu | F13: 10 | G13: 120 | H13: 1200 | I13: COMPLETED | J13: =_xlfn.XLOOKUP(C13,'STAFF TABLE'!A3:A12,'STAFF TABLE'!B3:B12) -> Amahle Zulu | K13: =_xlfn.XLOOKUP(C13,'STAFF TABLE'!$A$2:$A$11,'STAFF TABLE'!$C$2:$C$11) -> Durban Branch | L13: =_xlfn.XLOOKUP(C13,'STAFF TABLE'!$A$2:$A$11,'STAFF TABLE'!$D$2:$D$11) -> KZN | M13: =_xlfn.XLOOKUP(C13,'STAFF TABLE'!$A$2:$A$11,'STAFF TABLE'!$E$2:$E$11) -> 0.1 | N13: =_xlfn.XLOOKUP(D13,'PRODUCT CATALOGUE'!$A$2:$A$13,'PRODUCT CATALOGUE'!$B$2:$B$13) -> Printer Paper Ream | O13: =_xlfn.XLOOKUP(D13,'PRODUCT CATALOGUE'!$A$2:$A$13,'PRODUCT CATALOGUE'!$C$2:$C$13) -> Stationery | P13: =_xlfn.XLOOKUP(D13,'PRODUCT CATALOGUE'!$A$2:$A$13,'PRODUCT CATALOGUE'!$E$2:$E$13) -> 55 | Q13: 1200 | R13: =Q13-P13 -> 1145 | S13: =R13/Q13 -> 0.95416667 | T13: =M13*Q13 -> 120 | U13: =IF(S13>100%,"false","good") -> good
A14: TXN013 | B14: 2026-01-10 | C14: EM09 | D14: PR11 | E14: Lebo Mahlangu | F14: 1 | G14: 2800 | H14: 2800 | I14: COMPLETED | J14: =_xlfn.XLOOKUP(C14,'STAFF TABLE'!A4:A13,'STAFF TABLE'!B4:B13) -> David Moyo | K14: =_xlfn.XLOOKUP(C14,'STAFF TABLE'!$A$2:$A$11,'STAFF TABLE'!$C$2:$C$11) -> Polokwane Branch | L14: =_xlfn.XLOOKUP(C14,'STAFF TABLE'!$A$2:$A$11,'STAFF TABLE'!$D$2:$D$11) -> Limpopo | M14: =_xlfn.XLOOKUP(C14,'STAFF TABLE'!$A$2:$A$11,'STAFF TABLE'!$E$2:$E$11) -> 0.07 | N14: =_xlfn.XLOOKUP(D14,'PRODUCT CATALOGUE'!$A$2:$A$13,'PRODUCT CATALOGUE'!$B$2:$B$13) -> Filing Cabinet | O14: =_xlfn.XLOOKUP(D14,'PRODUCT CATALOGUE'!$A$2:$A$13,'PRODUCT CATALOGUE'!$C$2:$C$13) -> Furniture | P14: =_xlfn.XLOOKUP(D14,'PRODUCT CATALOGUE'!$A$2:$A$13,'PRODUCT CATALOGUE'!$E$2:$E$13) -> 1600 | Q14: 2800 | R14: =Q14-P14 -> 1200 | S14: =R14/Q14 -> 0.42857143 | T14: =M14*Q14 -> 196 | U14: =IF(S14>100%,"false","good") -> good
A15: TXN014 | B15: 2026-01-10 | C15: EM02 | D15: PR05 | E15: Fatima Patel | F15: 4 | G15: 1200 | H15: 4800 | I15: COMPLETED | J15: =_xlfn.XLOOKUP(C15,'STAFF TABLE'!A2:A11,'STAFF TABLE'!B2:B11) -> Priya Pillay | K15: =_xlfn.XLOOKUP(C15,'STAFF TABLE'!$A$2:$A$11,'STAFF TABLE'!$C$2:$C$11) -> Durban Branch | L15: =_xlfn.XLOOKUP(C15,'STAFF TABLE'!$A$2:$A$11,'STAFF TABLE'!$D$2:$D$11) -> KZN | M15: =_xlfn.XLOOKUP(C15,'STAFF TABLE'!$A$2:$A$11,'STAFF TABLE'!$E$2:$E$11) -> 0.1 | N15: =_xlfn.XLOOKUP(D15,'PRODUCT CATALOGUE'!$A$2:$A$13,'PRODUCT CATALOGUE'!$B$2:$B$13) -> Webcam HD | O15: =_xlfn.XLOOKUP(D15,'PRODUCT CATALOGUE'!$A$2:$A$13,'PRODUCT CATALOGUE'!$C$2:$C$13) -> Electronics | P15: =_xlfn.XLOOKUP(D15,'PRODUCT CATALOGUE'!$A$2:$A$13,'PRODUCT CATALOGUE'!$E$2:$E$13) -> 620 | Q15: 4800 | R15: =Q15-P15 -> 4180 | S15: =R15/Q15 -> 0.87083333 | T15: =M15*Q15 -> 480 | U15: =IF(S15>100%,"false","good") -> good
A16: TXN015 | B16: 2026-01-11 | C16: EM08 | D16: PR01 | E16: Nomsa Khumalo | F16: 1 | G16: 15000 | H16: 15000 | I16: COMPLETED | J16: =_xlfn.XLOOKUP(C16,'STAFF TABLE'!A6:A15,'STAFF TABLE'!B6:B15) -> Kefilwe Sithole | K16: =_xlfn.XLOOKUP(C16,'STAFF TABLE'!$A$2:$A$11,'STAFF TABLE'!$C$2:$C$11) -> Sandton Branch | L16: =_xlfn.XLOOKUP(C16,'STAFF TABLE'!$A$2:$A$11,'STAFF TABLE'!$D$2:$D$11) -> Gauteng | M16: =_xlfn.XLOOKUP(C16,'STAFF TABLE'!$A$2:$A$11,'STAFF TABLE'!$E$2:$E$11) -> 0.08 | N16: =_xlfn.XLOOKUP(D16,'PRODUCT CATALOGUE'!$A$2:$A$13,'PRODUCT CATALOGUE'!$B$2:$B$13) -> Gaming Laptop | O16: =_xlfn.XLOOKUP(D16,'PRODUCT CATALOGUE'!$A$2:$A$13,'PRODUCT CATALOGUE'!$C$2:$C$13) -> Electronics | P16: =_xlfn.XLOOKUP(D16,'PRODUCT CATALOGUE'!$A$2:$A$13,'PRODUCT CATALOGUE'!$E$2:$E$13) -> 9800 | Q16: 15000 | R16: =Q16-P16 -> 5200 | S16: =R16/Q16 -> 0.34666667 | T16: =M16*Q16 -> 1200 | U16: =IF(S16>100%,"false","good") -> good
A17: TXN016 | B17: 2026-01-12 | C17: EM04 | D17: PR04 | E17: Pieter van Wyk | F17: 1 | G17: 5500 | H17: 5500 | I17: COMPLETED | J17: =_xlfn.XLOOKUP(C17,'STAFF TABLE'!A2:A11,'STAFF TABLE'!B2:B11) -> Riaan Botha | K17: =_xlfn.XLOOKUP(C17,'STAFF TABLE'!$A$2:$A$11,'STAFF TABLE'!$C$2:$C$11) -> Sandton Branch | L17: =_xlfn.XLOOKUP(C17,'STAFF TABLE'!$A$2:$A$11,'STAFF TABLE'!$D$2:$D$11) -> Gauteng | M17: =_xlfn.XLOOKUP(C17,'STAFF TABLE'!$A$2:$A$11,'STAFF TABLE'!$E$2:$E$11) -> 0.08 | N17: =_xlfn.XLOOKUP(D17,'PRODUCT CATALOGUE'!$A$2:$A$13,'PRODUCT CATALOGUE'!$B$2:$B$13) -> Standing Desk | O17: =_xlfn.XLOOKUP(D17,'PRODUCT CATALOGUE'!$A$2:$A$13,'PRODUCT CATALOGUE'!$C$2:$C$13) -> Furniture | P17: =_xlfn.XLOOKUP(D17,'PRODUCT CATALOGUE'!$A$2:$A$13,'PRODUCT CATALOGUE'!$E$2:$E$13) -> 3100 | Q17: 5500 | R17: =Q17-P17 -> 2400 | S17: =R17/Q17 -> 0.43636364 | T17: =M17*Q17 -> 440 | U17: =IF(S17>100%,"false","good") -> good
A18: TXN017 | B18: 12/01/2026 | C18: EM06 | D18: PR07 | E18: Kefilwe Sithole | F18: -1 | G18: 2100 | I18: RETURNED | J18: =_xlfn.XLOOKUP(C18,'STAFF TABLE'!A3:A12,'STAFF TABLE'!B3:B12) -> Lebo Mahlangu | K18: =_xlfn.XLOOKUP(C18,'STAFF TABLE'!$A$2:$A$11,'STAFF TABLE'!$C$2:$C$11) -> Polokwane Branch | L18: =_xlfn.XLOOKUP(C18,'STAFF TABLE'!$A$2:$A$11,'STAFF TABLE'!$D$2:$D$11) -> Limpopo | M18: =_xlfn.XLOOKUP(C18,'STAFF TABLE'!$A$2:$A$11,'STAFF TABLE'!$E$2:$E$11) -> 0.07 | N18: =_xlfn.XLOOKUP(D18,'PRODUCT CATALOGUE'!$A$2:$A$13,'PRODUCT CATALOGUE'!$B$2:$B$13) -> Mechanical Keyboard | O18: =_xlfn.XLOOKUP(D18,'PRODUCT CATALOGUE'!$A$2:$A$13,'PRODUCT CATALOGUE'!$C$2:$C$13) -> Electronics | P18: =_xlfn.XLOOKUP(D18,'PRODUCT CATALOGUE'!$A$2:$A$13,'PRODUCT CATALOGUE'!$E$2:$E$13) -> 1100 | Q18: -2100 | R18: =Q18-P18 -> -3200 | S18: =R18/Q18 -> 1.5238095 | T18: =M18*Q18 -> -147 | U18: =IF(S18>100%,"false","good") -> false
A19: TXN018 | B19: 2026-01-13 | C19: EM01 | D19: PR06 | F19: 15 | G19: 350 | H19: 5250 | I19: COMPLETED | J19: =_xlfn.XLOOKUP(C19,'STAFF TABLE'!A2:A11,'STAFF TABLE'!B2:B11) -> Thabo Nkosi | K19: =_xlfn.XLOOKUP(C19,'STAFF TABLE'!$A$2:$A$11,'STAFF TABLE'!$C$2:$C$11) -> Sandton Branch | L19: =_xlfn.XLOOKUP(C19,'STAFF TABLE'!$A$2:$A$11,'STAFF TABLE'!$D$2:$D$11) -> Gauteng | M19: =_xlfn.XLOOKUP(C19,'STAFF TABLE'!$A$2:$A$11,'STAFF TABLE'!$E$2:$E$11) -> 0.08 | N19: =_xlfn.XLOOKUP(D19,'PRODUCT CATALOGUE'!$A$2:$A$13,'PRODUCT CATALOGUE'!$B$2:$B$13) -> Notebook Bundle | O19: =_xlfn.XLOOKUP(D19,'PRODUCT CATALOGUE'!$A$2:$A$13,'PRODUCT CATALOGUE'!$C$2:$C$13) -> Stationery | P19: =_xlfn.XLOOKUP(D19,'PRODUCT CATALOGUE'!$A$2:$A$13,'PRODUCT CATALOGUE'!$E$2:$E$13) -> 140 | Q19: 5250 | R19: =Q19-P19 -> 5110 | S19: =R19/Q19 -> 0.97333333 | T19: =M19*Q19 -> 420 | U19: =IF(S19>100%,"false","good") -> good
A20: TXN019 | B20: 2026-01-13 | C20: em06 | D20: PR03 | E20: Sipho Dlamini | F20: 2 | G20: 1800 | H20: 3600 | I20: COMPLETED | J20: =_xlfn.XLOOKUP(C20,'STAFF TABLE'!A5:A14,'STAFF TABLE'!B5:B14) -> Lebo Mahlangu | K20: =_xlfn.XLOOKUP(C20,'STAFF TABLE'!$A$2:$A$11,'STAFF TABLE'!$C$2:$C$11) -> Polokwane Branch | L20: =_xlfn.XLOOKUP(C20,'STAFF TABLE'!$A$2:$A$11,'STAFF TABLE'!$D$2:$D$11) -> Limpopo | M20: =_xlfn.XLOOKUP(C20,'STAFF TABLE'!$A$2:$A$11,'STAFF TABLE'!$E$2:$E$11) -> 0.07 | N20: =_xlfn.XLOOKUP(D20,'PRODUCT CATALOGUE'!$A$2:$A$13,'PRODUCT CATALOGUE'!$B$2:$B$13) -> Wireless Headset | O20: =_xlfn.XLOOKUP(D20,'PRODUCT CATALOGUE'!$A$2:$A$13,'PRODUCT CATALOGUE'!$C$2:$C$13) -> Electronics | P20: =_xlfn.XLOOKUP(D20,'PRODUCT CATALOGUE'!$A$2:$A$13,'PRODUCT CATALOGUE'!$E$2:$E$13) -> 950 | Q20: 3600 | R20: =Q20-P20 -> 2650 | S20: =R20/Q20 -> 0.73611111 | T20: =M20*Q20 -> 252 | U20: =IF(S20>100%,"false","good") -> good
A21: TXN020 | B21: 2026-01-14 | C21: EM10 | D21: PR09 | E21: David Moyo | F21: 3 | G21: 4800 | H21: 14400 | I21: COMPLETED | J21: =_xlfn.XLOOKUP(C21,'STAFF TABLE'!A11:A20,'STAFF TABLE'!B11:B20) -> Sipho Dlamini | K21: =_xlfn.XLOOKUP(C21,'STAFF TABLE'!$A$2:$A$11,'STAFF TABLE'!$C$2:$C$11) -> Durban Branch | L21: =_xlfn.XLOOKUP(C21,'STAFF TABLE'!$A$2:$A$11,'STAFF TABLE'!$D$2:$D$11) -> KZN | M21: =_xlfn.XLOOKUP(C21,'STAFF TABLE'!$A$2:$A$11,'STAFF TABLE'!$E$2:$E$11) -> 0.1 | N21: =_xlfn.XLOOKUP(D21,'PRODUCT CATALOGUE'!$A$2:$A$13,'PRODUCT CATALOGUE'!$B$2:$B$13) -> Monitor 27inch | O21: =_xlfn.XLOOKUP(D21,'PRODUCT CATALOGUE'!$A$2:$A$13,'PRODUCT CATALOGUE'!$C$2:$C$13) -> Electronics | P21: =_xlfn.XLOOKUP(D21,'PRODUCT CATALOGUE'!$A$2:$A$13,'PRODUCT CATALOGUE'!$E$2:$E$13) -> 2900 | Q21: 14400 | R21: =Q21-P21 -> 11500 | S21: =R21/Q21 -> 0.79861111 | T21: =M21*Q21 -> 1440 | U21: =IF(S21>100%,"false","good") -> good
A22: TXN021 | B22: 2026-01-15 | C22: EM07 | D22: PR02 | E22: Priya Pillay | F22: 2 | G22: 3200 | H22: 6400 | I22: PENDING | J22: =_xlfn.XLOOKUP(C22,'STAFF TABLE'!A2:A11,'STAFF TABLE'!B2:B11) -> Fatima Patel | K22: =_xlfn.XLOOKUP(C22,'STAFF TABLE'!$A$2:$A$11,'STAFF TABLE'!$C$2:$C$11) -> Cape Town Branch | L22: =_xlfn.XLOOKUP(C22,'STAFF TABLE'!$A$2:$A$11,'STAFF TABLE'!$D$2:$D$11) -> Western Cape | M22: =_xlfn.XLOOKUP(C22,'STAFF TABLE'!$A$2:$A$11,'STAFF TABLE'!$E$2:$E$11) -> 0.09 | N22: =_xlfn.XLOOKUP(D22,'PRODUCT CATALOGUE'!$A$2:$A$13,'PRODUCT CATALOGUE'!$B$2:$B$13) -> Office Chair | O22: =_xlfn.XLOOKUP(D22,'PRODUCT CATALOGUE'!$A$2:$A$13,'PRODUCT CATALOGUE'!$C$2:$C$13) -> Furniture | P22: =_xlfn.XLOOKUP(D22,'PRODUCT CATALOGUE'!$A$2:$A$13,'PRODUCT CATALOGUE'!$E$2:$E$13) -> 1750 | Q22: 6400 | R22: =Q22-P22 -> 4650 | S22: =R22/Q22 -> 0.7265625 | T22: =M22*Q22 -> 576 | U22: =IF(S22>100%,"false","good") -> good
A23: TXN022 | B23: 15/01/2026 | C23: EM03 | D23: PR10 | E23: Zanele Mokoena | F23: 6 | G23: 650 | H23: 3900 | I23: COMPLETED | J23: =_xlfn.XLOOKUP(C23,'STAFF TABLE'!A3:A12,'STAFF TABLE'!B3:B12) -> Zanele Dlamini | K23: =_xlfn.XLOOKUP(C23,'STAFF TABLE'!$A$2:$A$11,'STAFF TABLE'!$C$2:$C$11) -> Cape Town Branch | L23: =_xlfn.XLOOKUP(C23,'STAFF TABLE'!$A$2:$A$11,'STAFF TABLE'!$D$2:$D$11) -> Western Cape | M23: =_xlfn.XLOOKUP(C23,'STAFF TABLE'!$A$2:$A$11,'STAFF TABLE'!$E$2:$E$11) -> 0.09 | N23: =_xlfn.XLOOKUP(D23,'PRODUCT CATALOGUE'!$A$2:$A$13,'PRODUCT CATALOGUE'!$B$2:$B$13) -> Ergonomic Mouse | O23: =_xlfn.XLOOKUP(D23,'PRODUCT CATALOGUE'!$A$2:$A$13,'PRODUCT CATALOGUE'!$C$2:$C$13) -> Electronics | P23: =_xlfn.XLOOKUP(D23,'PRODUCT CATALOGUE'!$A$2:$A$13,'PRODUCT CATALOGUE'!$E$2:$E$13) -> 310 | Q23: 3900 | R23: =Q23-P23 -> 3590 | S23: =R23/Q23 -> 0.92051282 | T23: =M23*Q23 -> 351 | U23: =IF(S23>100%,"false","good") -> good
A24: TXN023 | B24: 2026-01-16 | C24: EM05 | D24: PR11 | E24: Riaan Botha | F24: 1 | G24: 2800 | H24: 2800 | I24: COMPLETED | J24: =_xlfn.XLOOKUP(C24,'STAFF TABLE'!A4:A13,'STAFF TABLE'!B4:B13) -> Amahle Zulu | K24: =_xlfn.XLOOKUP(C24,'STAFF TABLE'!$A$2:$A$11,'STAFF TABLE'!$C$2:$C$11) -> Durban Branch | L24: =_xlfn.XLOOKUP(C24,'STAFF TABLE'!$A$2:$A$11,'STAFF TABLE'!$D$2:$D$11) -> KZN | M24: =_xlfn.XLOOKUP(C24,'STAFF TABLE'!$A$2:$A$11,'STAFF TABLE'!$E$2:$E$11) -> 0.1 | N24: =_xlfn.XLOOKUP(D24,'PRODUCT CATALOGUE'!$A$2:$A$13,'PRODUCT CATALOGUE'!$B$2:$B$13) -> Filing Cabinet | O24: =_xlfn.XLOOKUP(D24,'PRODUCT CATALOGUE'!$A$2:$A$13,'PRODUCT CATALOGUE'!$C$2:$C$13) -> Furniture | P24: =_xlfn.XLOOKUP(D24,'PRODUCT CATALOGUE'!$A$2:$A$13,'PRODUCT CATALOGUE'!$E$2:$E$13) -> 1600 | Q24: 2800 | R24: =Q24-P24 -> 1200 | S24: =R24/Q24 -> 0.42857143 | T24: =M24*Q24 -> 280 | U24: =IF(S24>100%,"false","good") -> good
A25: TXN024 | B25: 2026-01-16 | C25: EM08 | D25: PR01 | E25: Amahle Zulu | F25: 2 | G25: 15000 | H25: 28000 | I25: COMPLETED | J25: =_xlfn.XLOOKUP(C25,'STAFF TABLE'!A5:A14,'STAFF TABLE'!B5:B14) -> Kefilwe Sithole | K25: =_xlfn.XLOOKUP(C25,'STAFF TABLE'!$A$2:$A$11,'STAFF TABLE'!$C$2:$C$11) -> Sandton Branch | L25: =_xlfn.XLOOKUP(C25,'STAFF TABLE'!$A$2:$A$11,'STAFF TABLE'!$D$2:$D$11) -> Gauteng | M25: =_xlfn.XLOOKUP(C25,'STAFF TABLE'!$A$2:$A$11,'STAFF TABLE'!$E$2:$E$11) -> 0.08 | N25: =_xlfn.XLOOKUP(D25,'PRODUCT CATALOGUE'!$A$2:$A$13,'PRODUCT CATALOGUE'!$B$2:$B$13) -> Gaming Laptop | O25: =_xlfn.XLOOKUP(D25,'PRODUCT CATALOGUE'!$A$2:$A$13,'PRODUCT CATALOGUE'!$C$2:$C$13) -> Electronics | P25: =_xlfn.XLOOKUP(D25,'PRODUCT CATALOGUE'!$A$2:$A$13,'PRODUCT CATALOGUE'!$E$2:$E$13) -> 9800 | Q25: 30000 | R25: =Q25-P25 -> 20200 | S25: =R25/Q25 -> 0.67333333 | T25: =M25*Q25 -> 2400 | U25: =IF(S25>100%,"false","good") -> good
A26: TXN025 | B26: 2026-01-17 | C26: EM02 | D26: PR08 | E26: Lebo Mahlangu | F26: 4 | G26: 890 | H26: 3560 | I26: COMPLETED | J26: =_xlfn.XLOOKUP(C26,'STAFF TABLE'!$A$2:$A$11,'STAFF TABLE'!$B$2:$B$11) -> Priya Pillay | K26: =_xlfn.XLOOKUP(C26,'STAFF TABLE'!$A$2:$A$11,'STAFF TABLE'!$C$2:$C$11) -> Durban Branch | L26: =_xlfn.XLOOKUP(C26,'STAFF TABLE'!$A$2:$A$11,'STAFF TABLE'!$D$2:$D$11) -> KZN | M26: =_xlfn.XLOOKUP(C26,'STAFF TABLE'!$A$2:$A$11,'STAFF TABLE'!$E$2:$E$11) -> 0.1 | N26: =_xlfn.XLOOKUP(D26,'PRODUCT CATALOGUE'!$A$2:$A$13,'PRODUCT CATALOGUE'!$B$2:$B$13) -> Whiteboard | O26: =_xlfn.XLOOKUP(D26,'PRODUCT CATALOGUE'!$A$2:$A$13,'PRODUCT CATALOGUE'!$C$2:$C$13) -> Stationery | P26: =_xlfn.XLOOKUP(D26,'PRODUCT CATALOGUE'!$A$2:$A$13,'PRODUCT CATALOGUE'!$E$2:$E$13) -> 420 | Q26: 3560 | R26: =Q26-P26 -> 3140 | S26: =R26/Q26 -> 0.88202247 | T26: =M26*Q26 -> 356 | U26: =IF(S26>100%,"false","good") -> good
A27: TXN026 | B27: 2026-01-19 | C27: EM09 | D27: PR06 | E27: Fatima Patel | F27: 20 | G27: 350 | H27: 7000 | I27: COMPLETED | J27: =_xlfn.XLOOKUP(C27,'STAFF TABLE'!$A$2:$A$11,'STAFF TABLE'!$B$2:$B$11) -> David Moyo | K27: =_xlfn.XLOOKUP(C27,'STAFF TABLE'!$A$2:$A$11,'STAFF TABLE'!$C$2:$C$11) -> Polokwane Branch | L27: =_xlfn.XLOOKUP(C27,'STAFF TABLE'!$A$2:$A$11,'STAFF TABLE'!$D$2:$D$11) -> Limpopo | M27: =_xlfn.XLOOKUP(C27,'STAFF TABLE'!$A$2:$A$11,'STAFF TABLE'!$E$2:$E$11) -> 0.07 | N27: =_xlfn.XLOOKUP(D27,'PRODUCT CATALOGUE'!$A$2:$A$13,'PRODUCT CATALOGUE'!$B$2:$B$13) -> Notebook Bundle | O27: =_xlfn.XLOOKUP(D27,'PRODUCT CATALOGUE'!$A$2:$A$13,'PRODUCT CATALOGUE'!$C$2:$C$13) -> Stationery | P27: =_xlfn.XLOOKUP(D27,'PRODUCT CATALOGUE'!$A$2:$A$13,'PRODUCT CATALOGUE'!$E$2:$E$13) -> 140 | Q27: 7000 | R27: =Q27-P27 -> 6860 | S27: =R27/Q27 -> 0.98 | T27: =M27*Q27 -> 490 | U27: =IF(S27>100%,"false","good") -> good
A28: TXN027 | B28: 19/01/2026 | C28: EM01 | D28: PR05 | E28: Nomsa Khumalo | F28: 2 | G28: 1200 | H28: 2400 | I28: COMPLETED | J28: =_xlfn.XLOOKUP(C28,'STAFF TABLE'!$A$2:$A$11,'STAFF TABLE'!$B$2:$B$11) -> Thabo Nkosi | K28: =_xlfn.XLOOKUP(C28,'STAFF TABLE'!$A$2:$A$11,'STAFF TABLE'!$C$2:$C$11) -> Sandton Branch | L28: =_xlfn.XLOOKUP(C28,'STAFF TABLE'!$A$2:$A$11,'STAFF TABLE'!$D$2:$D$11) -> Gauteng | M28: =_xlfn.XLOOKUP(C28,'STAFF TABLE'!$A$2:$A$11,'STAFF TABLE'!$E$2:$E$11) -> 0.08 | N28: =_xlfn.XLOOKUP(D28,'PRODUCT CATALOGUE'!$A$2:$A$13,'PRODUCT CATALOGUE'!$B$2:$B$13) -> Webcam HD | O28: =_xlfn.XLOOKUP(D28,'PRODUCT CATALOGUE'!$A$2:$A$13,'PRODUCT CATALOGUE'!$C$2:$C$13) -> Electronics | P28: =_xlfn.XLOOKUP(D28,'PRODUCT CATALOGUE'!$A$2:$A$13,'PRODUCT CATALOGUE'!$E$2:$E$13) -> 620 | Q28: 2400 | R28: =Q28-P28 -> 1780 | S28: =R28/Q28 -> 0.74166667 | T28: =M28*Q28 -> 192 | U28: =IF(S28>100%,"false","good") -> good
A29: TXN028 | B29: 2026-01-20 | C29: EM04 | D29: PR09 | E29: Pieter van Wyk | F29: 1 | G29: 4800 | H29: N/A | I29: COMPLETED | J29: =_xlfn.XLOOKUP(C29,'STAFF TABLE'!$A$2:$A$11,'STAFF TABLE'!$B$2:$B$11) -> Riaan Botha | K29: =_xlfn.XLOOKUP(C29,'STAFF TABLE'!$A$2:$A$11,'STAFF TABLE'!$C$2:$C$11) -> Sandton Branch | L29: =_xlfn.XLOOKUP(C29,'STAFF TABLE'!$A$2:$A$11,'STAFF TABLE'!$D$2:$D$11) -> Gauteng | M29: =_xlfn.XLOOKUP(C29,'STAFF TABLE'!$A$2:$A$11,'STAFF TABLE'!$E$2:$E$11) -> 0.08 | N29: =_xlfn.XLOOKUP(D29,'PRODUCT CATALOGUE'!$A$2:$A$13,'PRODUCT CATALOGUE'!$B$2:$B$13) -> Monitor 27inch | O29: =_xlfn.XLOOKUP(D29,'PRODUCT CATALOGUE'!$A$2:$A$13,'PRODUCT CATALOGUE'!$C$2:$C$13) -> Electronics | P29: =_xlfn.XLOOKUP(D29,'PRODUCT CATALOGUE'!$A$2:$A$13,'PRODUCT CATALOGUE'!$E$2:$E$13) -> 2900 | Q29: 4800 | R29: =Q29-P29 -> 1900 | S29: =R29/Q29 -> 0.39583333 | T29: =M29*Q29 -> 384 | U29: =IF(S29>100%,"false","good") -> good
A30: TXN029 | B30: 2026-01-20 | C30: EM07 | D30: PR12 | E30: Kefilwe Sithole | F30: 25 | G30: 120 | H30: 3000 | I30: COMPLETED | J30: =_xlfn.XLOOKUP(C30,'STAFF TABLE'!$A$2:$A$11,'STAFF TABLE'!$B$2:$B$11) -> Fatima Patel | K30: =_xlfn.XLOOKUP(C30,'STAFF TABLE'!$A$2:$A$11,'STAFF TABLE'!$C$2:$C$11) -> Cape Town Branch | L30: =_xlfn.XLOOKUP(C30,'STAFF TABLE'!$A$2:$A$11,'STAFF TABLE'!$D$2:$D$11) -> Western Cape | M30: =_xlfn.XLOOKUP(C30,'STAFF TABLE'!$A$2:$A$11,'STAFF TABLE'!$E$2:$E$11) -> 0.09 | N30: =_xlfn.XLOOKUP(D30,'PRODUCT CATALOGUE'!$A$2:$A$13,'PRODUCT CATALOGUE'!$B$2:$B$13) -> Printer Paper Ream | O30: =_xlfn.XLOOKUP(D30,'PRODUCT CATALOGUE'!$A$2:$A$13,'PRODUCT CATALOGUE'!$C$2:$C$13) -> Stationery | P30: =_xlfn.XLOOKUP(D30,'PRODUCT CATALOGUE'!$A$2:$A$13,'PRODUCT CATALOGUE'!$E$2:$E$13) -> 55 | Q30: 3000 | R30: =Q30-P30 -> 2945 | S30: =R30/Q30 -> 0.98166667 | T30: =M30*Q30 -> 270 | U30: =IF(S30>100%,"false","good") -> good
A31: TXN030 | B31: 2026-01-21 | C31: EM10 | D31: PR07 | E31: Sipho Dlamini | F31: 2 | G31: 2100 | H31: 4200 | I31: COMPLETED | J31: =_xlfn.XLOOKUP(C31,'STAFF TABLE'!$A$2:$A$11,'STAFF TABLE'!$B$2:$B$11) -> Sipho Dlamini | K31: =_xlfn.XLOOKUP(C31,'STAFF TABLE'!$A$2:$A$11,'STAFF TABLE'!$C$2:$C$11) -> Durban Branch | L31: =_xlfn.XLOOKUP(C31,'STAFF TABLE'!$A$2:$A$11,'STAFF TABLE'!$D$2:$D$11) -> KZN | M31: =_xlfn.XLOOKUP(C31,'STAFF TABLE'!$A$2:$A$11,'STAFF TABLE'!$E$2:$E$11) -> 0.1 | N31: =_xlfn.XLOOKUP(D31,'PRODUCT CATALOGUE'!$A$2:$A$13,'PRODUCT CATALOGUE'!$B$2:$B$13) -> Mechanical Keyboard | O31: =_xlfn.XLOOKUP(D31,'PRODUCT CATALOGUE'!$A$2:$A$13,'PRODUCT CATALOGUE'!$C$2:$C$13) -> Electronics | P31: =_xlfn.XLOOKUP(D31,'PRODUCT CATALOGUE'!$A$2:$A$13,'PRODUCT CATALOGUE'!$E$2:$E$13) -> 1100 | Q31: 4200 | R31: =Q31-P31 -> 3100 | S31: =R31/Q31 -> 0.73809524 | T31: =M31*Q31 -> 420 | U31: =IF(S31>100%,"false","good") -> good
A32: TXN031 | B32: 2026-02-03 | C32: EM03 | D32: PR01 | E32: David Moyo | F32: 1 | G32: 15000 | H32: 15000 | I32: COMPLETED | J32: =_xlfn.XLOOKUP(C32,'STAFF TABLE'!$A$2:$A$11,'STAFF TABLE'!$B$2:$B$11) -> Zanele Dlamini | K32: =_xlfn.XLOOKUP(C32,'STAFF TABLE'!$A$2:$A$11,'STAFF TABLE'!$C$2:$C$11) -> Cape Town Branch | L32: =_xlfn.XLOOKUP(C32,'STAFF TABLE'!$A$2:$A$11,'STAFF TABLE'!$D$2:$D$11) -> Western Cape | M32: =_xlfn.XLOOKUP(C32,'STAFF TABLE'!$A$2:$A$11,'STAFF TABLE'!$E$2:$E$11) -> 0.09 | N32: =_xlfn.XLOOKUP(D32,'PRODUCT CATALOGUE'!$A$2:$A$13,'PRODUCT CATALOGUE'!$B$2:$B$13) -> Gaming Laptop | O32: =_xlfn.XLOOKUP(D32,'PRODUCT CATALOGUE'!$A$2:$A$13,'PRODUCT CATALOGUE'!$C$2:$C$13) -> Electronics | P32: =_xlfn.XLOOKUP(D32,'PRODUCT CATALOGUE'!$A$2:$A$13,'PRODUCT CATALOGUE'!$E$2:$E$13) -> 9800 | Q32: 15000 | R32: =Q32-P32 -> 5200 | S32: =R32/Q32 -> 0.34666667 | T32: =M32*Q32 -> 1350 | U32: =IF(S32>100%,"false","good") -> good
A33: TXN032 | B33: 03/02/2026 | C33: EM06 | D33: PR04 | F33: 2 | G33: 5500 | H33: 11000 | I33: COMPLETED | J33: =_xlfn.XLOOKUP(C33,'STAFF TABLE'!$A$2:$A$11,'STAFF TABLE'!$B$2:$B$11) -> Lebo Mahlangu | K33: =_xlfn.XLOOKUP(C33,'STAFF TABLE'!$A$2:$A$11,'STAFF TABLE'!$C$2:$C$11) -> Polokwane Branch | L33: =_xlfn.XLOOKUP(C33,'STAFF TABLE'!$A$2:$A$11,'STAFF TABLE'!$D$2:$D$11) -> Limpopo | M33: =_xlfn.XLOOKUP(C33,'STAFF TABLE'!$A$2:$A$11,'STAFF TABLE'!$E$2:$E$11) -> 0.07 | N33: =_xlfn.XLOOKUP(D33,'PRODUCT CATALOGUE'!$A$2:$A$13,'PRODUCT CATALOGUE'!$B$2:$B$13) -> Standing Desk | O33: =_xlfn.XLOOKUP(D33,'PRODUCT CATALOGUE'!$A$2:$A$13,'PRODUCT CATALOGUE'!$C$2:$C$13) -> Furniture | P33: =_xlfn.XLOOKUP(D33,'PRODUCT CATALOGUE'!$A$2:$A$13,'PRODUCT CATALOGUE'!$E$2:$E$13) -> 3100 | Q33: 11000 | R33: =Q33-P33 -> 7900 | S33: =R33/Q33 -> 0.71818182 | T33: =M33*Q33 -> 770 | U33: =IF(S33>100%,"false","good") -> good
A34: TXN033 | B34: 2026-02-04 | C34: EM01 | D34: PR03 | E34: Priya Pillay | F34: 3 | G34: 1800 | H34: 5400 | I34: COMPLETED | J34: =_xlfn.XLOOKUP(C34,'STAFF TABLE'!$A$2:$A$11,'STAFF TABLE'!$B$2:$B$11) -> Thabo Nkosi | K34: =_xlfn.XLOOKUP(C34,'STAFF TABLE'!$A$2:$A$11,'STAFF TABLE'!$C$2:$C$11) -> Sandton Branch | L34: =_xlfn.XLOOKUP(C34,'STAFF TABLE'!$A$2:$A$11,'STAFF TABLE'!$D$2:$D$11) -> Gauteng | M34: =_xlfn.XLOOKUP(C34,'STAFF TABLE'!$A$2:$A$11,'STAFF TABLE'!$E$2:$E$11) -> 0.08 | N34: =_xlfn.XLOOKUP(D34,'PRODUCT CATALOGUE'!$A$2:$A$13,'PRODUCT CATALOGUE'!$B$2:$B$13) -> Wireless Headset | O34: =_xlfn.XLOOKUP(D34,'PRODUCT CATALOGUE'!$A$2:$A$13,'PRODUCT CATALOGUE'!$C$2:$C$13) -> Electronics | P34: =_xlfn.XLOOKUP(D34,'PRODUCT CATALOGUE'!$A$2:$A$13,'PRODUCT CATALOGUE'!$E$2:$E$13) -> 950 | Q34: 5400 | R34: =Q34-P34 -> 4450 | S34: =R34/Q34 -> 0.82407407 | T34: =M34*Q34 -> 432 | U34: =IF(S34>100%,"false","good") -> good
A35: TXN034 | B35: 2026-02-04 | C35: EM05 | D35: PR08 | E35: Zanele Mokoena | F35: 5 | G35: 890 | H35: 4450 | I35: COMPLETED | J35: =_xlfn.XLOOKUP(C35,'STAFF TABLE'!$A$2:$A$11,'STAFF TABLE'!$B$2:$B$11) -> Amahle Zulu | K35: =_xlfn.XLOOKUP(C35,'STAFF TABLE'!$A$2:$A$11,'STAFF TABLE'!$C$2:$C$11) -> Durban Branch | L35: =_xlfn.XLOOKUP(C35,'STAFF TABLE'!$A$2:$A$11,'STAFF TABLE'!$D$2:$D$11) -> KZN | M35: =_xlfn.XLOOKUP(C35,'STAFF TABLE'!$A$2:$A$11,'STAFF TABLE'!$E$2:$E$11) -> 0.1 | N35: =_xlfn.XLOOKUP(D35,'PRODUCT CATALOGUE'!$A$2:$A$13,'PRODUCT CATALOGUE'!$B$2:$B$13) -> Whiteboard | O35: =_xlfn.XLOOKUP(D35,'PRODUCT CATALOGUE'!$A$2:$A$13,'PRODUCT CATALOGUE'!$C$2:$C$13) -> Stationery | P35: =_xlfn.XLOOKUP(D35,'PRODUCT CATALOGUE'!$A$2:$A$13,'PRODUCT CATALOGUE'!$E$2:$E$13) -> 420 | Q35: 4450 | R35: =Q35-P35 -> 4030 | S35: =R35/Q35 -> 0.90561798 | T35: =M35*Q35 -> 445 | U35: =IF(S35>100%,"false","good") -> good
A36: TXN035 | B36: 2026-02-05 | C36: EM08 | D36: PR09 | E36: Riaan Botha | F36: 2 | G36: 4800 | H36: 9600 | I36: COMPLETED | J36: =_xlfn.XLOOKUP(C36,'STAFF TABLE'!$A$2:$A$11,'STAFF TABLE'!$B$2:$B$11) -> Kefilwe Sithole | K36: =_xlfn.XLOOKUP(C36,'STAFF TABLE'!$A$2:$A$11,'STAFF TABLE'!$C$2:$C$11) -> Sandton Branch | L36: =_xlfn.XLOOKUP(C36,'STAFF TABLE'!$A$2:$A$11,'STAFF TABLE'!$D$2:$D$11) -> Gauteng | M36: =_xlfn.XLOOKUP(C36,'STAFF TABLE'!$A$2:$A$11,'STAFF TABLE'!$E$2:$E$11) -> 0.08 | N36: =_xlfn.XLOOKUP(D36,'PRODUCT CATALOGUE'!$A$2:$A$13,'PRODUCT CATALOGUE'!$B$2:$B$13) -> Monitor 27inch | O36: =_xlfn.XLOOKUP(D36,'PRODUCT CATALOGUE'!$A$2:$A$13,'PRODUCT CATALOGUE'!$C$2:$C$13) -> Electronics | P36: =_xlfn.XLOOKUP(D36,'PRODUCT CATALOGUE'!$A$2:$A$13,'PRODUCT CATALOGUE'!$E$2:$E$13) -> 2900 | Q36: 9600 | R36: =Q36-P36 -> 6700 | S36: =R36/Q36 -> 0.69791667 | T36: =M36*Q36 -> 768 | U36: =IF(S36>100%,"false","good") -> good
A37: TXN036 | B37: 2026-02-05 | C37: EM02 | D37: PR06 | E37: Amahle Zulu | F37: 12 | G37: 350 | H37: 4200 | I37: COMPLETED | J37: =_xlfn.XLOOKUP(C37,'STAFF TABLE'!$A$2:$A$11,'STAFF TABLE'!$B$2:$B$11) -> Priya Pillay | K37: =_xlfn.XLOOKUP(C37,'STAFF TABLE'!$A$2:$A$11,'STAFF TABLE'!$C$2:$C$11) -> Durban Branch | L37: =_xlfn.XLOOKUP(C37,'STAFF TABLE'!$A$2:$A$11,'STAFF TABLE'!$D$2:$D$11) -> KZN | M37: =_xlfn.XLOOKUP(C37,'STAFF TABLE'!$A$2:$A$11,'STAFF TABLE'!$E$2:$E$11) -> 0.1 | N37: =_xlfn.XLOOKUP(D37,'PRODUCT CATALOGUE'!$A$2:$A$13,'PRODUCT CATALOGUE'!$B$2:$B$13) -> Notebook Bundle | O37: =_xlfn.XLOOKUP(D37,'PRODUCT CATALOGUE'!$A$2:$A$13,'PRODUCT CATALOGUE'!$C$2:$C$13) -> Stationery | P37: =_xlfn.XLOOKUP(D37,'PRODUCT CATALOGUE'!$A$2:$A$13,'PRODUCT CATALOGUE'!$E$2:$E$13) -> 140 | Q37: 4200 | R37: =Q37-P37 -> 4060 | S37: =R37/Q37 -> 0.96666667 | T37: =M37*Q37 -> 420 | U37: =IF(S37>100%,"false","good") -> good
A38: TXN037 | B38: 05/02/2026 | C38: EM09 | D38: PR01 | E38: Lebo Mahlangu | F38: 1 | G38: 15000 | H38: 15000 | I38: COMPLETED | J38: =_xlfn.XLOOKUP(C38,'STAFF TABLE'!$A$2:$A$11,'STAFF TABLE'!$B$2:$B$11) -> David Moyo | K38: =_xlfn.XLOOKUP(C38,'STAFF TABLE'!$A$2:$A$11,'STAFF TABLE'!$C$2:$C$11) -> Polokwane Branch | L38: =_xlfn.XLOOKUP(C38,'STAFF TABLE'!$A$2:$A$11,'STAFF TABLE'!$D$2:$D$11) -> Limpopo | M38: =_xlfn.XLOOKUP(C38,'STAFF TABLE'!$A$2:$A$11,'STAFF TABLE'!$E$2:$E$11) -> 0.07 | N38: =_xlfn.XLOOKUP(D38,'PRODUCT CATALOGUE'!$A$2:$A$13,'PRODUCT CATALOGUE'!$B$2:$B$13) -> Gaming Laptop | O38: =_xlfn.XLOOKUP(D38,'PRODUCT CATALOGUE'!$A$2:$A$13,'PRODUCT CATALOGUE'!$C$2:$C$13) -> Electronics | P38: =_xlfn.XLOOKUP(D38,'PRODUCT CATALOGUE'!$A$2:$A$13,'PRODUCT CATALOGUE'!$E$2:$E$13) -> 9800 | Q38: 15000 | R38: =Q38-P38 -> 5200 | S38: =R38/Q38 -> 0.34666667 | T38: =M38*Q38 -> 1050 | U38: =IF(S38>100%,"false","good") -> good
A39: TXN038 | B39: 2026-02-06 | C39: EM07 | D39: PR11 | E39: Fatima Patel | F39: 3 | G39: 2800 | H39: 8400 | I39: COMPLETED | J39: =_xlfn.XLOOKUP(C39,'STAFF TABLE'!$A$2:$A$11,'STAFF TABLE'!$B$2:$B$11) -> Fatima Patel | K39: =_xlfn.XLOOKUP(C39,'STAFF TABLE'!$A$2:$A$11,'STAFF TABLE'!$C$2:$C$11) -> Cape Town Branch | L39: =_xlfn.XLOOKUP(C39,'STAFF TABLE'!$A$2:$A$11,'STAFF TABLE'!$D$2:$D$11) -> Western Cape | M39: =_xlfn.XLOOKUP(C39,'STAFF TABLE'!$A$2:$A$11,'STAFF TABLE'!$E$2:$E$11) -> 0.09 | N39: =_xlfn.XLOOKUP(D39,'PRODUCT CATALOGUE'!$A$2:$A$13,'PRODUCT CATALOGUE'!$B$2:$B$13) -> Filing Cabinet | O39: =_xlfn.XLOOKUP(D39,'PRODUCT CATALOGUE'!$A$2:$A$13,'PRODUCT CATALOGUE'!$C$2:$C$13) -> Furniture | P39: =_xlfn.XLOOKUP(D39,'PRODUCT CATALOGUE'!$A$2:$A$13,'PRODUCT CATALOGUE'!$E$2:$E$13) -> 1600 | Q39: 8400 | R39: =Q39-P39 -> 6800 | S39: =R39/Q39 -> 0.80952381 | T39: =M39*Q39 -> 756 | U39: =IF(S39>100%,"false","good") -> good
A40: TXN039 | B40: 2026-02-07 | C40: EM04 | D40: PR05 | E40: Nomsa Khumalo | F40: 4 | G40: 1200 | H40: 4800 | I40: COMPLETED | J40: =_xlfn.XLOOKUP(C40,'STAFF TABLE'!$A$2:$A$11,'STAFF TABLE'!$B$2:$B$11) -> Riaan Botha | K40: =_xlfn.XLOOKUP(C40,'STAFF TABLE'!$A$2:$A$11,'STAFF TABLE'!$C$2:$C$11) -> Sandton Branch | L40: =_xlfn.XLOOKUP(C40,'STAFF TABLE'!$A$2:$A$11,'STAFF TABLE'!$D$2:$D$11) -> Gauteng | M40: =_xlfn.XLOOKUP(C40,'STAFF TABLE'!$A$2:$A$11,'STAFF TABLE'!$E$2:$E$11) -> 0.08 | N40: =_xlfn.XLOOKUP(D40,'PRODUCT CATALOGUE'!$A$2:$A$13,'PRODUCT CATALOGUE'!$B$2:$B$13) -> Webcam HD | O40: =_xlfn.XLOOKUP(D40,'PRODUCT CATALOGUE'!$A$2:$A$13,'PRODUCT CATALOGUE'!$C$2:$C$13) -> Electronics | P40: =_xlfn.XLOOKUP(D40,'PRODUCT CATALOGUE'!$A$2:$A$13,'PRODUCT CATALOGUE'!$E$2:$E$13) -> 620 | Q40: 4800 | R40: =Q40-P40 -> 4180 | S40: =R40/Q40 -> 0.87083333 | T40: =M40*Q40 -> 384 | U40: =IF(S40>100%,"false","good") -> good
...

Sheet CLEANED DATA
A2: TxnID | B2: Date | C2: EmpID | D2: ProductID | E2: CustomerName | F2: Quantity | G2: Unit Price (R) | H2: Total Revenue (R) | I2: Status | J2: Rep Name | K2: Branch | L2: Region | M2: Commission Rate | N2: Product Name | O2: Category | P2: Cost Price (R) | Q2: Revenue Check | R2: Profit (R) | S2: Profit Margin % | T2: Commission Earned (R) | U2: Performance Flag
A3: TXN001 | B3: 46027 | C3: EM01 | D3: PR09 | E3: Fatima Patel | F3: 2 | G3: 4800 | H3: 9600 | I3: COMPLETED | J3: Thabo Nkosi | K3: Sandton Branch | L3: Gauteng | M3: 0.08 | N3: Monitor 27inch | O3: Electronics | P3: 2900 | Q3: 9600 | R3: 6700 | S3: 0.69791667 | T3: 768 | U3: good
A4: TXN002 | B4: 46027 | C4: EM03 | D4: PR01 | F4: 1 | G4: 15000 | H4: 15000 | I4: COMPLETED | J4: Zanele Dlamini | K4: Cape Town Branch | L4: Western Cape | M4: 0.09 | N4: Gaming Laptop | O4: Electronics | P4: 9800 | Q4: 15000 | R4: 5200 | S4: 0.34666667 | T4: 1350 | U4: good
A5: TXN003 | B5: 46028 | C5: EM05 | D5: PR07 | E5: Nomsa Khumalo | F5: 3 | G5: 2100 | H5: 6300 | I5: COMPLETED | J5: Amahle Zulu | K5: Durban Branch | L5: KZN | M5: 0.1 | N5: Mechanical Keyboard | O5: Electronics | P5: 1100 | Q5: 6300 | R5: 5200 | S5: 0.82539683 | T5: 630 | U5: good
A6: TXN004 | B6: 46028 | C6: EM02 | D6: PR04 | E6: Pieter van Wyk | F6: 1 | G6: 5500 | H6: 5500 | I6: COMPLETED | J6: Priya Pillay | K6: Durban Branch | L6: KZN | M6: 0.1 | N6: Standing Desk | O6: Furniture | P6: 3100 | Q6: 5500 | R6: 2400 | S6: 0.43636364 | T6: 550 | U6: good
A7: TXN005 | B7: 46029 | C7: EM08 | D7: PR06 | E7: Kefilwe Sithole | F7: 2 | G7: 350 | H7: 700 | I7: COMPLETED | J7: Kefilwe Sithole | K7: Sandton Branch | L7: Gauteng | M7: 0.08 | N7: Notebook Bundle | O7: Stationery | P7: 140 | Q7: 700 | R7: 560 | S7: 0.8 | T7: 56 | U7: good
A8: TXN006 | B8: 46029 | C8: EM06 | D8: PR02 | E8: Sipho Dlamini | F8: 1 | G8: 3200 | H8: 3200 | I8: PENDING | J8: Lebo Mahlangu | K8: Polokwane Branch | L8: Limpopo | M8: 0.07 | N8: Office Chair | O8: Furniture | P8: 1750 | Q8: 3200 | R8: 1450 | S8: 0.453125 | T8: 224 | U8: good
A9: TXN007 | B9: 46029 | C9: EM01 | D9: PR10 | E9: David Moyo | F9: 5 | G9: 650 | H9: 3250 | I9: COMPLETED | J9: Thabo Nkosi | K9: Sandton Branch | L9: Gauteng | M9: 0.08 | N9: Ergonomic Mouse | O9: Electronics | P9: 310 | Q9: 3250 | R9: 2940 | S9: 0.90461538 | T9: 260 | U9: good
A10: TXN008 | B10: 46030 | C10: EM04 | D10: PR03 | E10: Priya Pillay | F10: 4 | G10: 1800 | H10: 7200 | I10: COMPLETED | J10: Riaan Botha | K10: Sandton Branch | L10: Gauteng | M10: 0.08 | N10: Wireless Headset | O10: Electronics | P10: 950 | Q10: 7200 | R10: 6250 | S10: 0.86805556 | T10: 576 | U10: good
A11: TXN009 | B11: 46030 | C11: EM07 | D11: PR01 | E11: Zanele Mokoena | F11: 2 | G11: 15000 | H11: 25000 | I11: COMPLETED | J11: Fatima Patel | K11: Cape Town Branch | L11: Western Cape | M11: 0.09 | N11: Gaming Laptop | O11: Electronics | P11: 9800 | Q11: 30000 | R11: 20200 | S11: 0.67333333 | T11: 2700 | U11: good
A12: TXN010 | B12: 46031 | C12: EM10 | D12: PR08 | F12: 3 | G12: 890 | H12: 2670 | I12: CANCELLED | J12: Sipho Dlamini | K12: Durban Branch | L12: KZN | M12: 0.1 | N12: Whiteboard | O12: Stationery | P12: 420 | Q12: 2670 | R12: 2250 | S12: 0.84269663 | T12: 267 | U12: good
A13: TXN011 | B13: 46031 | C13: EM03 | D13: PR09 | E13: Riaan Botha | F13: 1 | G13: 4800 | H13: 4800 | I13: COMPLETED | J13: Zanele Dlamini | K13: Cape Town Branch | L13: Western Cape | M13: 0.09 | N13: Monitor 27inch | O13: Electronics | P13: 2900 | Q13: 4800 | R13: 1900 | S13: 0.39583333 | T13: 432 | U13: good
A14: TXN012 | B14: 46031 | C14: EM05 | D14: PR12 | E14: Amahle Zulu | F14: 10 | G14: 120 | H14: 1200 | I14: COMPLETED | J14: Amahle Zulu | K14: Durban Branch | L14: KZN | M14: 0.1 | N14: Printer Paper Ream | O14: Stationery | P14: 55 | Q14: 1200 | R14: 1145 | S14: 0.95416667 | T14: 120 | U14: good
A15: TXN013 | B15: 46032 | C15: EM09 | D15: PR11 | E15: Lebo Mahlangu | F15: 1 | G15: 2800 | H15: 2800 | I15: COMPLETED | J15: David Moyo | K15: Polokwane Branch | L15: Limpopo | M15: 0.07 | N15: Filing Cabinet | O15: Furniture | P15: 1600 | Q15: 2800 | R15: 1200 | S15: 0.42857143 | T15: 196 | U15: good
A16: TXN014 | B16: 46032 | C16: EM02 | D16: PR05 | E16: Fatima Patel | F16: 4 | G16: 1200 | H16: 4800 | I16: COMPLETED | J16: Priya Pillay | K16: Durban Branch | L16: KZN | M16: 0.1 | N16: Webcam HD | O16: Electronics | P16: 620 | Q16: 4800 | R16: 4180 | S16: 0.87083333 | T16: 480 | U16: good
A17: TXN015 | B17: 46033 | C17: EM08 | D17: PR01 | E17: Nomsa Khumalo | F17: 1 | G17: 15000 | H17: 15000 | I17: COMPLETED | J17: Kefilwe Sithole | K17: Sandton Branch | L17: Gauteng | M17: 0.08 | N17: Gaming Laptop | O17: Electronics | P17: 9800 | Q17: 15000 | R17: 5200 | S17: 0.34666667 | T17: 1200 | U17: good
A18: TXN016 | B18: 46034 | C18: EM04 | D18: PR04 | E18: Pieter van Wyk | F18: 1 | G18: 5500 | H18: 5500 | I18: COMPLETED | J18: Riaan Botha | K18: Sandton Branch | L18: Gauteng | M18: 0.08 | N18: Standing Desk | O18: Furniture | P18: 3100 | Q18: 5500 | R18: 2400 | S18: 0.43636364 | T18: 440 | U18: good
A19: TXN017 | B19: 46034 | C19: EM06 | D19: PR07 | E19: Kefilwe Sithole | F19: -1 | G19: 2100 | I19: RETURNED | J19: Lebo Mahlangu | K19: Polokwane Branch | L19: Limpopo | M19: 0.07 | N19: Mechanical Keyboard | O19: Electronics | P19: 1100 | Q19: -2100 | R19: -3200 | S19: 1.5238095 | T19: -147 | U19: false
A20: TXN018 | B20: 46035 | C20: EM01 | D20: PR06 | F20: 15 | G20: 350 | H20: 5250 | I20: COMPLETED | J20: Thabo Nkosi | K20: Sandton Branch | L20: Gauteng | M20: 0.08 | N20: Notebook Bundle | O20: Stationery | P20: 140 | Q20: 5250 | R20: 5110 | S20: 0.97333333 | T20: 420 | U20: good
A21: TXN019 | B21: 46035 | C21: em06 | D21: PR03 | E21: Sipho Dlamini | F21: 2 | G21: 1800 | H21: 3600 | I21: COMPLETED | J21: Lebo Mahlangu | K21: Polokwane Branch | L21: Limpopo | M21: 0.07 | N21: Wireless Headset | O21: Electronics | P21: 950 | Q21: 3600 | R21: 2650 | S21: 0.73611111 | T21: 252 | U21: good
A22: TXN020 | B22: 46036 | C22: EM10 | D22: PR09 | E22: David Moyo | F22: 3 | G22: 4800 | H22: 14400 | I22: COMPLETED | J22: Sipho Dlamini | K22: Durban Branch | L22: KZN | M22: 0.1 | N22: Monitor 27inch | O22: Electronics | P22: 2900 | Q22: 14400 | R22: 11500 | S22: 0.79861111 | T22: 1440 | U22: good
A23: TXN021 | B23: 46037 | C23: EM07 | D23: PR02 | E23: Priya Pillay | F23: 2 | G23: 3200 | H23: 6400 | I23: PENDING | J23: Fatima Patel | K23: Cape Town Branch | L23: Western Cape | M23: 0.09 | N23: Office Chair | O23: Furniture | P23: 1750 | Q23: 6400 | R23: 4650 | S23: 0.7265625 | T23: 576 | U23: good
A24: TXN022 | B24: 46037 | C24: EM03 | D24: PR10 | E24: Zanele Mokoena | F24: 6 | G24: 650 | H24: 3900 | I24: COMPLETED | J24: Zanele Dlamini | K24: Cape Town Branch | L24: Western Cape | M24: 0.09 | N24: Ergonomic Mouse | O24: Electronics | P24: 310 | Q24: 3900 | R24: 3590 | S24: 0.92051282 | T24: 351 | U24: good
A25: TXN023 | B25: 46038 | C25: EM05 | D25: PR11 | E25: Riaan Botha | F25: 1 | G25: 2800 | H25: 2800 | I25: COMPLETED | J25: Amahle Zulu | K25: Durban Branch | L25: KZN | M25: 0.1 | N25: Filing Cabinet | O25: Furniture | P25: 1600 | Q25: 2800 | R25: 1200 | S25: 0.42857143 | T25: 280 | U25: good
A26: TXN024 | B26: 46038 | C26: EM08 | D26: PR01 | E26: Amahle Zulu | F26: 2 | G26: 15000 | H26: 28000 | I26: COMPLETED | J26: Kefilwe Sithole | K26: Sandton Branch | L26: Gauteng | M26: 0.08 | N26: Gaming Laptop | O26: Electronics | P26: 9800 | Q26: 30000 | R26: 20200 | S26: 0.67333333 | T26: 2400 | U26: good
A27: TXN025 | B27: 46039 | C27: EM02 | D27: PR08 | E27: Lebo Mahlangu | F27: 4 | G27: 890 | H27: 3560 | I27: COMPLETED | J27: Priya Pillay | K27: Durban Branch | L27: KZN | M27: 0.1 | N27: Whiteboard | O27: Stationery | P27: 420 | Q27: 3560 | R27: 3140 | S27: 0.88202247 | T27: 356 | U27: good
A28: TXN026 | B28: 46041 | C28: EM09 | D28: PR06 | E28: Fatima Patel | F28: 20 | G28: 350 | H28: 7000 | I28: COMPLETED | J28: David Moyo | K28: Polokwane Branch | L28: Limpopo | M28: 0.07 | N28: Notebook Bundle | O28: Stationery | P28: 140 | Q28: 7000 | R28: 6860 | S28: 0.98 | T28: 490 | U28: good
A29: TXN027 | B29: 46041 | C29: EM01 | D29: PR05 | E29: Nomsa Khumalo | F29: 2 | G29: 1200 | H29: 2400 | I29: COMPLETED | J29: Thabo Nkosi | K29: Sandton Branch | L29: Gauteng | M29: 0.08 | N29: Webcam HD | O29: Electronics | P29: 620 | Q29: 2400 | R29: 1780 | S29: 0.74166667 | T29: 192 | U29: good
A30: TXN028 | B30: 46042 | C30: EM04 | D30: PR09 | E30: Pieter van Wyk | F30: 1 | G30: 4800 | H30: N/A | I30: COMPLETED | J30: Riaan Botha | K30: Sandton Branch | L30: Gauteng | M30: 0.08 | N30: Monitor 27inch | O30: Electronics | P30: 2900 | Q30: 4800 | R30: 1900 | S30: 0.39583333 | T30: 384 | U30: good
A31: TXN029 | B31: 46042 | C31: EM07 | D31: PR12 | E31: Kefilwe Sithole | F31: 25 | G31: 120 | H31: 3000 | I31: COMPLETED | J31: Fatima Patel | K31: Cape Town Branch | L31: Western Cape | M31: 0.09 | N31: Printer Paper Ream | O31: Stationery | P31: 55 | Q31: 3000 | R31: 2945 | S31: 0.98166667 | T31: 270 | U31: good
A32: TXN030 | B32: 46043 | C32: EM10 | D32: PR07 | E32: Sipho Dlamini | F32: 2 | G32: 2100 | H32: 4200 | I32: COMPLETED | J32: Sipho Dlamini | K32: Durban Branch | L32: KZN | M32: 0.1 | N32: Mechanical Keyboard | O32: Electronics | P32: 1100 | Q32: 4200 | R32: 3100 | S32: 0.73809524 | T32: 420 | U32: good
A33: TXN031 | B33: 46056 | C33: EM03 | D33: PR01 | E33: David Moyo | F33: 1 | G33: 15000 | H33: 15000 | I33: COMPLETED | J33: Zanele Dlamini | K33: Cape Town Branch | L33: Western Cape | M33: 0.09 | N33: Gaming Laptop | O33: Electronics | P33: 9800 | Q33: 15000 | R33: 5200 | S33: 0.34666667 | T33: 1350 | U33: good
A34: TXN032 | B34: 46056 | C34: EM06 | D34: PR04 | F34: 2 | G34: 5500 | H34: 11000 | I34: COMPLETED | J34: Lebo Mahlangu | K34: Polokwane Branch | L34: Limpopo | M34: 0.07 | N34: Standing Desk | O34: Furniture | P34: 3100 | Q34: 11000 | R34: 7900 | S34: 0.71818182 | T34: 770 | U34: good
A35: TXN033 | B35: 46057 | C35: EM01 | D35: PR03 | E35: Priya Pillay | F35: 3 | G35: 1800 | H35: 5400 | I35: COMPLETED | J35: Thabo Nkosi | K35: Sandton Branch | L35: Gauteng | M35: 0.08 | N35: Wireless Headset | O35: Electronics | P35: 950 | Q35: 5400 | R35: 4450 | S35: 0.82407407 | T35: 432 | U35: good
A36: TXN034 | B36: 46057 | C36: EM05 | D36: PR08 | E36: Zanele Mokoena | F36: 5 | G36: 890 | H36: 4450 | I36: COMPLETED | J36: Amahle Zulu | K36: Durban Branch | L36: KZN | M36: 0.1 | N36: Whiteboard | O36: Stationery | P36: 420 | Q36: 4450 | R36: 4030 | S36: 0.90561798 | T36: 445 | U36: good
A37: TXN035 | B37: 46058 | C37: EM08 | D37: PR09 | E37: Riaan Botha | F37: 2 | G37: 4800 | H37: 9600 | I37: COMPLETED | J37: Kefilwe Sithole | K37: Sandton Branch | L37: Gauteng | M37: 0.08 | N37: Monitor 27inch | O37: Electronics | P37: 2900 | Q37: 9600 | R37: 6700 | S37: 0.69791667 | T37: 768 | U37: good
A38: TXN036 | B38: 46058 | C38: EM02 | D38: PR06 | E38: Amahle Zulu | F38: 12 | G38: 350 | H38: 4200 | I38: COMPLETED | J38: Priya Pillay | K38: Durban Branch | L38: KZN | M38: 0.1 | N38: Notebook Bundle | O38: Stationery | P38: 140 | Q38: 4200 | R38: 4060 | S38: 0.96666667 | T38: 420 | U38: good
A39: TXN037 | B39: 46058 | C39: EM09 | D39: PR01 | E39: Lebo Mahlangu | F39: 1 | G39: 15000 | H39: 15000 | I39: COMPLETED | J39: David Moyo | K39: Polokwane Branch | L39: Limpopo | M39: 0.07 | N39: Gaming Laptop | O39: Electronics | P39: 9800 | Q39: 15000 | R39: 5200 | S39: 0.34666667 | T39: 1050 | U39: good
A40: TXN038 | B40: 46059 | C40: EM07 | D40: PR11 | E40: Fatima Patel | F40: 3 | G40: 2800 | H40: 8400 | I40: COMPLETED | J40: Fatima Patel | K40: Cape Town Branch | L40: Western Cape | M40: 0.09 | N40: Filing Cabinet | O40: Furniture | P40: 1600 | Q40: 8400 | R40: 6800 | S40: 0.80952381 | T40: 756 | U40: good
A41: TXN039 | B41: 46060 | C41: EM04 | D41: PR05 | E41: Nomsa Khumalo | F41: 4 | G41: 1200 | H41: 4800 | I41: COMPLETED | J41: Riaan Botha | K41: Sandton Branch | L41: Gauteng | M41: 0.08 | N41: Webcam HD | O41: Electronics | P41: 620 | Q41: 4800 | R41: 4180 | S41: 0.87083333 | T41: 384 | U41: good
...

Sheet BOARD REPORT
A1: Q1 2026 BUSINESS PERFORMANCE REPORT — BOARD PRESENTATION
A2: Prepared by: Anotida Kanzara | C2: Date: 5/17/2026
A3: Period: January – March 2026 | C3: Status: DRAFT
A5: EXECUTIVE SUMMARY
A6: Total Q1 Revenue (R): 499 030.00 | C6: Total Transactions: 80
A7: Best Performing Branch: Sandton Branch | C7: Top Sales Rep: Kefilwe Sithole
A8: Best Selling Category: Electronics | C8: Total Commission Paid (R): 32 316
A9: Total Profit (R):335 345.00 | C9: Avg Profit Margin %: 62
A11: SECTION 1 — REVENUE BY BRANCH
A12: Branch | B12: Total Transactions | C12: Total Revenue (R) | D12: Total Profit (R) | E12: % of Total Revenue
A13: Sandton Branch | B13: 25 | C13: 171720 | D13: 124150 | E13: =D13/C13 -> 0.72297927
A14: Durban Branch | B14: 24 | C14: 143280 | D14: 94655 | E14: =D14/C14 -> 0.66062954
A15: Cape Town Branch | B15: 16 | C15: 110060 | D15: 73345 | E15: =D15/C15 -> 0.66640923
A16: Polokwane Branch | B16: 15 | C16: 73970 | D16: 43195 | E16: =D16/C16 -> 0.58395295
A17: GRAND TOTAL | B17: 80 | C17: 499030 | D17: 335345 | E17: =D17/C17 -> 0.67199367
A19: SECTION 2 — REVENUE BY PRODUCT CATEGORY
A20: Category | B20: Total Transactions | C20: Total Revenue (R) | D20: Avg Order Value (R) | E20: % of Total Revenue
A21: Electronics | B21: 44 | C21: 346150 | D21: 230400 | E21: =D21/C21 -> 0.6656074
A22: Furniture | B22: 18 | C22: 92000 | D22: 71700 | E22: =D22/C22 -> 0.77934783
A23: Stationery | B23: 18 | C23: 60880 | D23: 8390 | E23: =D23/C23 -> 0.13781209
A24: GRAND TOTAL | B24: 80 | C24: 499030 | D24: 310490 | E24: =D24/C24 -> 0.62218704
A26: SECTION 3 — TOP SALES REPS
A27: Rep Name | B27: Branch | C27: Total Revenue (R) | D27: Commission Earned (R) | E27: Performance Flag
A28: Kefilwe Sithole | B28: Sandton Branch | C28: 90300 | D28: 7464 | E28: Good
A29: Thabo Nkosi | B29: Sandton Branch | C29: 58270 | D29: 4661.6 | E29: Good
A30: Fatima Patel | B30: Cape Town Branch | C30: 56260 | D30: 5513.4 | E30: Good
A31: Zanele Dlamini | B31: Cape Town Branch | C31: 53800 | D31: 4716 | E31: Needs Investigation
A32: Amahle Zulu | B32: Durban Branch | C32: 52200 | D32: 5220 | E32: Good
A33: Priya Pillay | B33: Durban Branch | C33: 47410 | D33: 4741 | E33: Good
A34: SECTION 4 — MONTHLY REVENUE TREND
A35: Month | B35: Total Transactions | C35: Total Revenue (R) | D35: Month-on-Month Change
A36: January 2026 | B36: 30 | C36: 197030 | D36: 197030
A37: February 2026 | B37: 30 | C37: 184030 | D37: =C37-C36/C37 -> 184028.93
A38: March 2026 | B38: 20 | C38: 117970 | D38: =C38-C37/C38 -> 117968.44
A40: SECTION 5 — ORDERS REQUIRING INVESTIGATION
A41: TxnID | B41: Issue | C41: Action Required | D41: Assigned To | E41: Priority
A42: TXN009 | B42: Revenue mismatch recorded vs correct | C42: Verify with sales rep | E42: High
A43: TXN017 | B43: Negative quantity — possible return | C43: Confirm with manager | E43: Medium
A44: TXN024 | B44: Revenue mismatch recorded vs correct | C44: Verify with sales rep | E44: High
A45: TXN028 | B45: Revenue shows N/A | C45: Get correct figure from rep | E45: High
...
